Workbook

Sheet data
A1: QLI Number | B1: document_id | C1: currency | D1: customer_name | E1: deal_number | F1: document_name | G1: document_type | H1: entity | I1: invoice_date | J1: invoice_number | K1: legal_customer_name | L1: media_reference | M1: payment_term | N1: Po Number | O1: project_name | P1: supplier_name | Q1: total_invoice_amount | R1: vendor_name | S1: vsow_number | T1: __is_deleted | U1: __patch_offset | V1: vsow_document_id | W1: vsow_currency | X1: vsow_customer_name | Y1: vsow_deal_number | Z1: vsow_document_name | AA1: vsow_media_reference | AB1: vsow_payment_term | AC1: vsow_po_number | AD1: vsow_project_name | AE1: vsow_supplier_name | AF1: vsow_total_cost | AG1: vsow_total_cost_numeric | AH1: vsow_vsow_number | AI1: vsow___is_deleted | AJ1: vsow___patch_offset | AK1: line_item_primary_key_ | AL1: line_item_address | AM1: line_item_arc | AN1: line_item_bill_feature | AO1: line_item_billing_id | AP1: Item Description | AQ1: line_item_charge_type | AR1: line_item_city | AS1: line_item_correction_reasoning | AT1: line_item_customer | AU1: line_item_discount | AV1: line_item_document_rid | AW1: line_item_document_type | AX1: line_item_equipment_cost | AY1: line_item_expected_line_item_match_reasoning | AZ1: line_item_expected_line_item_match_status | BA1: line_item_in_evals | BB1: line_item_is_extraction_validated | BC1: line_item_is_mapping_validated | BD1: Item Code | BE1: line_item_item_description | BF1: line_item_last_validation_timestamp | BG1: line_item_last_validation_timestamp_tz | BH1: line_item_make | BI1: line_item_model | BJ1: MRC | BK1: line_item_needs_review | BL1: NRC | BM1: line_item_oem | BN1: OTC | BO1: line_item_page_number | BP1: line_item_page_rid | BQ1: line_item_part_number | BR1: line_item_previous_month_mrc | BS1: line_item_qrc_unit | BT1: Quantity | BU1: line_item_row_number | BV1: serial_number | BW1: line_item_service_end_date | BX1: line_item_service_start_date | BY1: line_item_sheet_name | BZ1: Site Id | CA1: line_item_site_name | CB1: line_item_state | CC1: line_item_status | CD1: line_item_support_cost | CE1: line_item_tax_amount | CF1: line_item_tax_percentage | CG1: line_item_tenure | CH1: line_item_total_amount | CI1: line_item_total_mrc | CJ1: line_item_total_otc_nrc_value | CK1: UP | CL1: line_item_zip | CM1: line_item___is_deleted | CN1: line_item___patch_offset
A2: QLI00001 | B2: ri.mio.main.media-item.0199713b-dbcf-7ebd-9cc7-6e4ba33fe6f4 | C2: CAD | D2: Equinix Canada, Ltd. | F2: Quote2-PO3000196864-EQUINIX-ATT+Wipro+Canada_Renewal+Post-Novation+(7+Months)__Quote_Num_1-223208968420+ATT+Sign+20230124.pdf | G2: Quote | H2: AT&T | L2: {"mimeType":"application/pdf","reference":{"type":"mediaSetViewItem","mediaSetViewItem":{"mediaSetRid":"ri.mio.main.media-set.7a7aadd5-adcf-42ac-9e71-12078d56f27e","mediaSetViewRid":"ri.mio.main.view.5660cab0-05c2-4700-94bc-c64529e38113","mediaItemRid":"ri.mio.main.media-item.0199713b-dbcf-7ebd-9cc7-6e4ba33fe6f4"}}} | N2: PO3000196864 | P2: Equinix Canada, Ltd. | T2: FALSE | U2: -1 | AK2: ri.mio.main.media-item.0199713b-dbcf-7ebd-9cc7-6e4ba33fe6f4_1_1 | AP2: Private Cage With KVA Based Power | AV2: ri.mio.main.media-item.0199713b-dbcf-7ebd-9cc7-6e4ba33fe6f4 | AW2: Quote | BD2: SPC00002 | BJ2: 30316 | BL2: 0 | BO2: 1 | BP2: ri.mio.main.media-item.0199713b-dbcf-7ebd-9cc7-6e4ba33fe6f4_0 | BT2: 1 | BU2: 1 | BV2: 7-100000400339 | BX2: 44896 | BZ2: MT1 | CA2: MT1 | CI2: 30316 | CM2: FALSE | CN2: 37290
A3: QLI00002 | B3: ri.mio.main.media-item.0199713b-dbcf-7ebd-9cc7-6e4ba33fe6f4 | C3: CAD | D3: Equinix Canada, Ltd. | F3: Quote2-PO3000196864-EQUINIX-ATT+Wipro+Canada_Renewal+Post-Novation+(7+Months)__Quote_Num_1-223208968420+ATT+Sign+20230124.pdf | G3: Quote | H3: AT&T | L3: {"mimeType":"application/pdf","reference":{"type":"mediaSetViewItem","mediaSetViewItem":{"mediaSetRid":"ri.mio.main.media-set.7a7aadd5-adcf-42ac-9e71-12078d56f27e","mediaSetViewRid":"ri.mio.main.view.5660cab0-05c2-4700-94bc-c64529e38113","mediaItemRid":"ri.mio.main.media-item.0199713b-dbcf-7ebd-9cc7-6e4ba33fe6f4"}}} | N3: PO3000196864 | P3: Equinix Canada, Ltd. | T3: FALSE | U3: -1 | AK3: ri.mio.main.media-item.0199713b-dbcf-7ebd-9cc7-6e4ba33fe6f4_1_2 | AP3: Cage - Customer Provided Cabinet - 12 Cabinets - 53 KVA | AV3: ri.mio.main.media-item.0199713b-dbcf-7ebd-9cc7-6e4ba33fe6f4 | AW3: Quote | BD3: CAG00001 | BJ3: 0 | BL3: 15158 | BO3: 1 | BP3: ri.mio.main.media-item.0199713b-dbcf-7ebd-9cc7-6e4ba33fe6f4_0 | BT3: 53 | BU3: 2 | BV3: 0811814 | BX3: 44896 | BZ3: MT1 | CA3: MT1 | CI3: 0 | CM3: FALSE | CN3: 37290
A4: QLI00003 | B4: ri.mio.main.media-item.0199713b-dbcf-7ebd-9cc7-6e4ba33fe6f4 | C4: CAD | D4: Equinix Canada, Ltd. | F4: Quote2-PO3000196864-EQUINIX-ATT+Wipro+Canada_Renewal+Post-Novation+(7+Months)__Quote_Num_1-223208968420+ATT+Sign+20230124.pdf | G4: Quote | H4: AT&T | L4: {"mimeType":"application/pdf","reference":{"type":"mediaSetViewItem","mediaSetViewItem":{"mediaSetRid":"ri.mio.main.media-set.7a7aadd5-adcf-42ac-9e71-12078d56f27e","mediaSetViewRid":"ri.mio.main.view.5660cab0-05c2-4700-94bc-c64529e38113","mediaItemRid":"ri.mio.main.media-item.0199713b-dbcf-7ebd-9cc7-6e4ba33fe6f4"}}} | N4: PO3000196864 | P4: Equinix Canada, Ltd. | T4: FALSE | U4: -1 | AK4: ri.mio.main.media-item.0199713b-dbcf-7ebd-9cc7-6e4ba33fe6f4_1_3 | AP4: AC Power | AV4: ri.mio.main.media-item.0199713b-dbcf-7ebd-9cc7-6e4ba33fe6f4 | AW4: Quote | BD4: POW00001 | BJ4: 0 | BL4: 15158 | BO4: 1 | BP4: ri.mio.main.media-item.0199713b-dbcf-7ebd-9cc7-6e4ba33fe6f4_0 | BT4: 53 | BU4: 3 | BV4: 7-100000401078 | BX4: 44896 | BZ4: MT1 | CA4: MT1 | CI4: 0 | CM4: FALSE | CN4: 37290
A5: QLI00004 | B5: ri.mio.main.media-item.0199713b-dbcf-7ebd-9cc7-6e4ba33fe6f4 | C5: CAD | D5: Equinix Canada, Ltd. | F5: Quote2-PO3000196864-EQUINIX-ATT+Wipro+Canada_Renewal+Post-Novation+(7+Months)__Quote_Num_1-223208968420+ATT+Sign+20230124.pdf | G5: Quote | H5: AT&T | L5: {"mimeType":"application/pdf","reference":{"type":"mediaSetViewItem","mediaSetViewItem":{"mediaSetRid":"ri.mio.main.media-set.7a7aadd5-adcf-42ac-9e71-12078d56f27e","mediaSetViewRid":"ri.mio.main.view.5660cab0-05c2-4700-94bc-c64529e38113","mediaItemRid":"ri.mio.main.media-item.0199713b-dbcf-7ebd-9cc7-6e4ba33fe6f4"}}} | N5: PO3000196864 | P5: Equinix Canada, Ltd. | T5: FALSE | U5: -1 | AK5: ri.mio.main.media-item.0199713b-dbcf-7ebd-9cc7-6e4ba33fe6f4_2_1 | AP5: AC Circuit - 208v - 20-amp - Three Phase - Redundant | AV5: ri.mio.main.media-item.0199713b-dbcf-7ebd-9cc7-6e4ba33fe6f4 | AW5: Quote | BD5: POW00003 | BJ5: 0 | BO5: 2 | BP5: ri.mio.main.media-item.0199713b-dbcf-7ebd-9cc7-6e4ba33fe6f4_1 | BT5: 1 | BU5: 1 | BV5: 100247282.MT1 | BX5: 44896 | CI5: 0 | CM5: FALSE | CN5: 33590
A6: QLI00005 | B6: ri.mio.main.media-item.0199713b-dbcf-7ebd-9cc7-6e4ba33fe6f4 | C6: CAD | D6: Equinix Canada, Ltd. | F6: Quote2-PO3000196864-EQUINIX-ATT+Wipro+Canada_Renewal+Post-Novation+(7+Months)__Quote_Num_1-223208968420+ATT+Sign+20230124.pdf | G6: Quote | H6: AT&T | L6: {"mimeType":"application/pdf","reference":{"type":"mediaSetViewItem","mediaSetViewItem":{"mediaSetRid":"ri.mio.main.media-set.7a7aadd5-adcf-42ac-9e71-12078d56f27e","mediaSetViewRid":"ri.mio.main.view.5660cab0-05c2-4700-94bc-c64529e38113","mediaItemRid":"ri.mio.main.media-item.0199713b-dbcf-7ebd-9cc7-6e4ba33fe6f4"}}} | N6: PO3000196864 | P6: Equinix Canada, Ltd. | T6: FALSE | U6: -1 | AK6: ri.mio.main.media-item.0199713b-dbcf-7ebd-9cc7-6e4ba33fe6f4_2_10 | AP6: Cabinet - 3.53 kVA - Open Cabinet | AV6: ri.mio.main.media-item.0199713b-dbcf-7ebd-9cc7-6e4ba33fe6f4 | AW6: Quote | BD6: CAB00001 | BJ6: 0 | BO6: 2 | BP6: ri.mio.main.media-item.0199713b-dbcf-7ebd-9cc7-6e4ba33fe6f4_1 | BT6: 1 | BU6: 10 | BV6: 0204-00121279 | BX6: 44896 | CI6: 0 | CM6: FALSE | CN6: 33590
A7: QLI00006 | B7: ri.mio.main.media-item.0199713b-dbcf-7ebd-9cc7-6e4ba33fe6f4 | C7: CAD | D7: Equinix Canada, Ltd. | F7: Quote2-PO3000196864-EQUINIX-ATT+Wipro+Canada_Renewal+Post-Novation+(7+Months)__Quote_Num_1-223208968420+ATT+Sign+20230124.pdf | G7: Quote | H7: AT&T | L7: {"mimeType":"application/pdf","reference":{"type":"mediaSetViewItem","mediaSetViewItem":{"mediaSetRid":"ri.mio.main.media-set.7a7aadd5-adcf-42ac-9e71-12078d56f27e","mediaSetViewRid":"ri.mio.main.view.5660cab0-05c2-4700-94bc-c64529e38113","mediaItemRid":"ri.mio.main.media-item.0199713b-dbcf-7ebd-9cc7-6e4ba33fe6f4"}}} | N7: PO3000196864 | P7: Equinix Canada, Ltd. | T7: FALSE | U7: -1 | AK7: ri.mio.main.media-item.0199713b-dbcf-7ebd-9cc7-6e4ba33fe6f4_2_11 | AP7: Cabinet - 3.53 kVA - Open Cabinet | AV7: ri.mio.main.media-item.0199713b-dbcf-7ebd-9cc7-6e4ba33fe6f4 | AW7: Quote | BD7: CAB00001 | BJ7: 0 | BO7: 2 | BP7: ri.mio.main.media-item.0199713b-dbcf-7ebd-9cc7-6e4ba33fe6f4_1 | BT7: 1 | BU7: 11 | BV7: 0201-00121276 | BX7: 44896 | CI7: 0 | CM7: FALSE | CN7: 33590
A8: QLI00007 | B8: ri.mio.main.media-item.0199713b-dbcf-7ebd-9cc7-6e4ba33fe6f4 | C8: CAD | D8: Equinix Canada, Ltd. | F8: Quote2-PO3000196864-EQUINIX-ATT+Wipro+Canada_Renewal+Post-Novation+(7+Months)__Quote_Num_1-223208968420+ATT+Sign+20230124.pdf | G8: Quote | H8: AT&T | L8: {"mimeType":"application/pdf","reference":{"type":"mediaSetViewItem","mediaSetViewItem":{"mediaSetRid":"ri.mio.main.media-set.7a7aadd5-adcf-42ac-9e71-12078d56f27e","mediaSetViewRid":"ri.mio.main.view.5660cab0-05c2-4700-94bc-c64529e38113","mediaItemRid":"ri.mio.main.media-item.0199713b-dbcf-7ebd-9cc7-6e4ba33fe6f4"}}} | N8: PO3000196864 | P8: Equinix Canada, Ltd. | T8: FALSE | U8: -1 | AK8: ri.mio.main.media-item.0199713b-dbcf-7ebd-9cc7-6e4ba33fe6f4_2_12 | AP8: Cabinet - 3.53 kVA - Open Cabinet | AV8: ri.mio.main.media-item.0199713b-dbcf-7ebd-9cc7-6e4ba33fe6f4 | AW8: Quote | BD8: CAB00001 | BJ8: 0 | BO8: 2 | BP8: ri.mio.main.media-item.0199713b-dbcf-7ebd-9cc7-6e4ba33fe6f4_1 | BT8: 1 | BU8: 12 | BV8: 0126-00121273 | BX8: 44896 | CI8: 0 | CM8: FALSE | CN8: 33590
A9: QLI00008 | B9: ri.mio.main.media-item.0199713b-dbcf-7ebd-9cc7-6e4ba33fe6f4 | C9: CAD | D9: Equinix Canada, Ltd. | F9: Quote2-PO3000196864-EQUINIX-ATT+Wipro+Canada_Renewal+Post-Novation+(7+Months)__Quote_Num_1-223208968420+ATT+Sign+20230124.pdf | G9: Quote | H9: AT&T | L9: {"mimeType":"application/pdf","reference":{"type":"mediaSetViewItem","mediaSetViewItem":{"mediaSetRid":"ri.mio.main.media-set.7a7aadd5-adcf-42ac-9e71-12078d56f27e","mediaSetViewRid":"ri.mio.main.view.5660cab0-05c2-4700-94bc-c64529e38113","mediaItemRid":"ri.mio.main.media-item.0199713b-dbcf-7ebd-9cc7-6e4ba33fe6f4"}}} | N9: PO3000196864 | P9: Equinix Canada, Ltd. | T9: FALSE | U9: -1 | AK9: ri.mio.main.media-item.0199713b-dbcf-7ebd-9cc7-6e4ba33fe6f4_2_13 | AP9: Cabinet - 3.53 kVA - Open Cabinet | AV9: ri.mio.main.media-item.0199713b-dbcf-7ebd-9cc7-6e4ba33fe6f4 | AW9: Quote | BD9: CAB00001 | BJ9: 0 | BO9: 2 | BP9: ri.mio.main.media-item.0199713b-dbcf-7ebd-9cc7-6e4ba33fe6f4_1 | BT9: 1 | BU9: 13 | BV9: 0209-00121278 | BX9: 44896 | CI9: 0 | CM9: FALSE | CN9: 33590
A10: QLI00009 | B10: ri.mio.main.media-item.0199713b-dbcf-7ebd-9cc7-6e4ba33fe6f4 | C10: CAD | D10: Equinix Canada, Ltd. | F10: Quote2-PO3000196864-EQUINIX-ATT+Wipro+Canada_Renewal+Post-Novation+(7+Months)__Quote_Num_1-223208968420+ATT+Sign+20230124.pdf | G10: Quote | H10: AT&T | L10: {"mimeType":"application/pdf","reference":{"type":"mediaSetViewItem","mediaSetViewItem":{"mediaSetRid":"ri.mio.main.media-set.7a7aadd5-adcf-42ac-9e71-12078d56f27e","mediaSetViewRid":"ri.mio.main.view.5660cab0-05c2-4700-94bc-c64529e38113","mediaItemRid":"ri.mio.main.media-item.0199713b-dbcf-7ebd-9cc7-6e4ba33fe6f4"}}} | N10: PO3000196864 | P10: Equinix Canada, Ltd. | T10: FALSE | U10: -1 | AK10: ri.mio.main.media-item.0199713b-dbcf-7ebd-9cc7-6e4ba33fe6f4_2_14 | AP10: Demarcation Point | AV10: ri.mio.main.media-item.0199713b-dbcf-7ebd-9cc7-6e4ba33fe6f4 | AW10: Quote | BD10: CC00004 | BJ10: 0 | BO10: 2 | BP10: ri.mio.main.media-item.0199713b-dbcf-7ebd-9cc7-6e4ba33fe6f4_1 | BT10: 1 | BU10: 14 | BV10: 0000-00726560 | BX10: 44896 | CI10: 0 | CM10: FALSE | CN10: 33590
A11: QLI00010 | B11: ri.mio.main.media-item.0199713b-dbcf-7ebd-9cc7-6e4ba33fe6f4 | C11: CAD | D11: Equinix Canada, Ltd. | F11: Quote2-PO3000196864-EQUINIX-ATT+Wipro+Canada_Renewal+Post-Novation+(7+Months)__Quote_Num_1-223208968420+ATT+Sign+20230124.pdf | G11: Quote | H11: AT&T | L11: {"mimeType":"application/pdf","reference":{"type":"mediaSetViewItem","mediaSetViewItem":{"mediaSetRid":"ri.mio.main.media-set.7a7aadd5-adcf-42ac-9e71-12078d56f27e","mediaSetViewRid":"ri.mio.main.view.5660cab0-05c2-4700-94bc-c64529e38113","mediaItemRid":"ri.mio.main.media-item.0199713b-dbcf-7ebd-9cc7-6e4ba33fe6f4"}}} | N11: PO3000196864 | P11: Equinix Canada, Ltd. | T11: FALSE | U11: -1 | AK11: ri.mio.main.media-item.0199713b-dbcf-7ebd-9cc7-6e4ba33fe6f4_2_15 | AP11: Cabinet - 3.53 kVA - Open Cabinet | AV11: ri.mio.main.media-item.0199713b-dbcf-7ebd-9cc7-6e4ba33fe6f4 | AW11: Quote | BD11: CAB00001 | BJ11: 0 | BO11: 2 | BP11: ri.mio.main.media-item.0199713b-dbcf-7ebd-9cc7-6e4ba33fe6f4_1 | BT11: 1 | BU11: 15 | BV11: 0301-00121280 | BX11: 44896 | CI11: 0 | CM11: FALSE | CN11: 33590
A12: QLI00011 | B12: ri.mio.main.media-item.0199713b-dbcf-7ebd-9cc7-6e4ba33fe6f4 | C12: CAD | D12: Equinix Canada, Ltd. | F12: Quote2-PO3000196864-EQUINIX-ATT+Wipro+Canada_Renewal+Post-Novation+(7+Months)__Quote_Num_1-223208968420+ATT+Sign+20230124.pdf | G12: Quote | H12: AT&T | L12: {"mimeType":"application/pdf","reference":{"type":"mediaSetViewItem","mediaSetViewItem":{"mediaSetRid":"ri.mio.main.media-set.7a7aadd5-adcf-42ac-9e71-12078d56f27e","mediaSetViewRid":"ri.mio.main.view.5660cab0-05c2-4700-94bc-c64529e38113","mediaItemRid":"ri.mio.main.media-item.0199713b-dbcf-7ebd-9cc7-6e4ba33fe6f4"}}} | N12: PO3000196864 | P12: Equinix Canada, Ltd. | T12: FALSE | U12: -1 | AK12: ri.mio.main.media-item.0199713b-dbcf-7ebd-9cc7-6e4ba33fe6f4_2_16 | AP12: Cross Connect | AV12: ri.mio.main.media-item.0199713b-dbcf-7ebd-9cc7-6e4ba33fe6f4 | AW12: Quote | BD12: CC00001 | BJ12: 320 | BO12: 2 | BP12: ri.mio.main.media-item.0199713b-dbcf-7ebd-9cc7-6e4ba33fe6f4_1 | BT12: 1 | BU12: 16 | BV12: 7-10000394303 | BX12: 44896 | CI12: 320 | CM12: FALSE | CN12: 33590
A13: QLI00012 | B13: ri.mio.main.media-item.0199713b-dbcf-7ebd-9cc7-6e4ba33fe6f4 | C13: CAD | D13: Equinix Canada, Ltd. | F13: Quote2-PO3000196864-EQUINIX-ATT+Wipro+Canada_Renewal+Post-Novation+(7+Months)__Quote_Num_1-223208968420+ATT+Sign+20230124.pdf | G13: Quote | H13: AT&T | L13: {"mimeType":"application/pdf","reference":{"type":"mediaSetViewItem","mediaSetViewItem":{"mediaSetRid":"ri.mio.main.media-set.7a7aadd5-adcf-42ac-9e71-12078d56f27e","mediaSetViewRid":"ri.mio.main.view.5660cab0-05c2-4700-94bc-c64529e38113","mediaItemRid":"ri.mio.main.media-item.0199713b-dbcf-7ebd-9cc7-6e4ba33fe6f4"}}} | N13: PO3000196864 | P13: Equinix Canada, Ltd. | T13: FALSE | U13: -1 | AK13: ri.mio.main.media-item.0199713b-dbcf-7ebd-9cc7-6e4ba33fe6f4_2_17 | AP13: Network Cable Connection - POTS - Z-side IBX- MT1 | AV13: ri.mio.main.media-item.0199713b-dbcf-7ebd-9cc7-6e4ba33fe6f4 | AW13: Quote | BD13: CC00001 | BJ13: 320 | BO13: 2 | BP13: ri.mio.main.media-item.0199713b-dbcf-7ebd-9cc7-6e4ba33fe6f4_1 | BT13: 1 | BU13: 17 | BV13: 100168372 | BX13: 44896 | BZ13: MT1 | CI13: 320 | CM13: FALSE | CN13: 33590
A14: QLI00013 | B14: ri.mio.main.media-item.0199713b-dbcf-7ebd-9cc7-6e4ba33fe6f4 | C14: CAD | D14: Equinix Canada, Ltd. | F14: Quote2-PO3000196864-EQUINIX-ATT+Wipro+Canada_Renewal+Post-Novation+(7+Months)__Quote_Num_1-223208968420+ATT+Sign+20230124.pdf | G14: Quote | H14: AT&T | L14: {"mimeType":"application/pdf","reference":{"type":"mediaSetViewItem","mediaSetViewItem":{"mediaSetRid":"ri.mio.main.media-set.7a7aadd5-adcf-42ac-9e71-12078d56f27e","mediaSetViewRid":"ri.mio.main.view.5660cab0-05c2-4700-94bc-c64529e38113","mediaItemRid":"ri.mio.main.media-item.0199713b-dbcf-7ebd-9cc7-6e4ba33fe6f4"}}} | N14: PO3000196864 | P14: Equinix Canada, Ltd. | T14: FALSE | U14: -1 | AK14: ri.mio.main.media-item.0199713b-dbcf-7ebd-9cc7-6e4ba33fe6f4_2_18 | AP14: Configurable Accessories | AV14: ri.mio.main.media-item.0199713b-dbcf-7ebd-9cc7-6e4ba33fe6f4 | AW14: Quote | BD14: PS00004 | BJ14: 0 | BL14: 0 | BO14: 2 | BP14: ri.mio.main.media-item.0199713b-dbcf-7ebd-9cc7-6e4ba33fe6f4_1 | BT14: 1 | BU14: 18 | BV14: 7-10000800310 | BX14: 44896 | CI14: 30636 | CM14: FALSE | CN14: 33590
A15: QLI00014 | B15: ri.mio.main.media-item.0199713b-dbcf-7ebd-9cc7-6e4ba33fe6f4 | C15: CAD | D15: Equinix Canada, Ltd. | F15: Quote2-PO3000196864-EQUINIX-ATT+Wipro+Canada_Renewal+Post-Novation+(7+Months)__Quote_Num_1-223208968420+ATT+Sign+20230124.pdf | G15: Quote | H15: AT&T | L15: {"mimeType":"application/pdf","reference":{"type":"mediaSetViewItem","mediaSetViewItem":{"mediaSetRid":"ri.mio.main.media-set.7a7aadd5-adcf-42ac-9e71-12078d56f27e","mediaSetViewRid":"ri.mio.main.view.5660cab0-05c2-4700-94bc-c64529e38113","mediaItemRid":"ri.mio.main.media-item.0199713b-dbcf-7ebd-9cc7-6e4ba33fe6f4"}}} | N15: PO3000196864 | P15: Equinix Canada, Ltd. | T15: FALSE | U15: -1 | AK15: ri.mio.main.media-item.0199713b-dbcf-7ebd-9cc7-6e4ba33fe6f4_2_19 | AP15: Patch Panel | AV15: ri.mio.main.media-item.0199713b-dbcf-7ebd-9cc7-6e4ba33fe6f4 | AW15: Quote | BD15: CC00001 | BL15: 200 | BO15: 2 | BP15: ri.mio.main.media-item.0199713b-dbcf-7ebd-9cc7-6e4ba33fe6f4_1 | BT15: 1 | BU15: 19 | BV15: PWP-000-1000529 | BX15: 44896 | CI15: 0 | CM15: FALSE | CN15: 33590
A16: QLI00015 | B16: ri.mio.main.media-item.0199713b-dbcf-7ebd-9cc7-6e4ba33fe6f4 | C16: CAD | D16: Equinix Canada, Ltd. | F16: Quote2-PO3000196864-EQUINIX-ATT+Wipro+Canada_Renewal+Post-Novation+(7+Months)__Quote_Num_1-223208968420+ATT+Sign+20230124.pdf | G16: Quote | H16: AT&T | L16: {"mimeType":"application/pdf","reference":{"type":"mediaSetViewItem","mediaSetViewItem":{"mediaSetRid":"ri.mio.main.media-set.7a7aadd5-adcf-42ac-9e71-12078d56f27e","mediaSetViewRid":"ri.mio.main.view.5660cab0-05c2-4700-94bc-c64529e38113","mediaItemRid":"ri.mio.main.media-item.0199713b-dbcf-7ebd-9cc7-6e4ba33fe6f4"}}} | N16: PO3000196864 | P16: Equinix Canada, Ltd. | T16: FALSE | U16: -1 | AK16: ri.mio.main.media-item.0199713b-dbcf-7ebd-9cc7-6e4ba33fe6f4_2_2 | AP16: AC Circuit - 208v - 20-amp - Three Phase - Redundant | AV16: ri.mio.main.media-item.0199713b-dbcf-7ebd-9cc7-6e4ba33fe6f4 | AW16: Quote | BD16: POW00003 | BJ16: 0 | BO16: 2 | BP16: ri.mio.main.media-item.0199713b-dbcf-7ebd-9cc7-6e4ba33fe6f4_1 | BT16: 1 | BU16: 2 | BV16: 100247288.MT1 | BX16: 44896 | CI16: 0 | CM16: FALSE | CN16: 33590
A17: QLI00016 | B17: ri.mio.main.media-item.0199713b-dbcf-7ebd-9cc7-6e4ba33fe6f4 | C17: CAD | D17: Equinix Canada, Ltd. | F17: Quote2-PO3000196864-EQUINIX-ATT+Wipro+Canada_Renewal+Post-Novation+(7+Months)__Quote_Num_1-223208968420+ATT+Sign+20230124.pdf | G17: Quote | H17: AT&T | L17: {"mimeType":"application/pdf","reference":{"type":"mediaSetViewItem","mediaSetViewItem":{"mediaSetRid":"ri.mio.main.media-set.7a7aadd5-adcf-42ac-9e71-12078d56f27e","mediaSetViewRid":"ri.mio.main.view.5660cab0-05c2-4700-94bc-c64529e38113","mediaItemRid":"ri.mio.main.media-item.0199713b-dbcf-7ebd-9cc7-6e4ba33fe6f4"}}} | N17: PO3000196864 | P17: Equinix Canada, Ltd. | T17: FALSE | U17: -1 | AK17: ri.mio.main.media-item.0199713b-dbcf-7ebd-9cc7-6e4ba33fe6f4_2_20 | AP17: Configurable Accessories | AV17: ri.mio.main.media-item.0199713b-dbcf-7ebd-9cc7-6e4ba33fe6f4 | AW17: Quote | BD17: PS00004 | BJ17: 0 | BL17: 0 | BO17: 2 | BP17: ri.mio.main.media-item.0199713b-dbcf-7ebd-9cc7-6e4ba33fe6f4_1 | BT17: 1 | BU17: 20 | BV17: 7-10000837239 | BX17: 44896 | CM17: FALSE | CN17: 33590
A18: QLI00017 | B18: ri.mio.main.media-item.0199713b-dbcf-7ebd-9cc7-6e4ba33fe6f4 | C18: CAD | D18: Equinix Canada, Ltd. | F18: Quote2-PO3000196864-EQUINIX-ATT+Wipro+Canada_Renewal+Post-Novation+(7+Months)__Quote_Num_1-223208968420+ATT+Sign+20230124.pdf | G18: Quote | H18: AT&T | L18: {"mimeType":"application/pdf","reference":{"type":"mediaSetViewItem","mediaSetViewItem":{"mediaSetRid":"ri.mio.main.media-set.7a7aadd5-adcf-42ac-9e71-12078d56f27e","mediaSetViewRid":"ri.mio.main.view.5660cab0-05c2-4700-94bc-c64529e38113","mediaItemRid":"ri.mio.main.media-item.0199713b-dbcf-7ebd-9cc7-6e4ba33fe6f4"}}} | N18: PO3000196864 | P18: Equinix Canada, Ltd. | T18: FALSE | U18: -1 | AK18: ri.mio.main.media-item.0199713b-dbcf-7ebd-9cc7-6e4ba33fe6f4_2_21 | AP18: Patch Panel | AV18: ri.mio.main.media-item.0199713b-dbcf-7ebd-9cc7-6e4ba33fe6f4 | AW18: Quote | BD18: CC00001 | BL18: 0 | BO18: 2 | BP18: ri.mio.main.media-item.0199713b-dbcf-7ebd-9cc7-6e4ba33fe6f4_1 | BT18: 1 | BU18: 21 | BV18: PP-0303:13870772 | BX18: 44896 | CI18: 0 | CM18: FALSE | CN18: 33590
A19: QLI00018 | B19: ri.mio.main.media-item.0199713b-dbcf-7ebd-9cc7-6e4ba33fe6f4 | C19: CAD | D19: Equinix Canada, Ltd. | F19: Quote2-PO3000196864-EQUINIX-ATT+Wipro+Canada_Renewal+Post-Novation+(7+Months)__Quote_Num_1-223208968420+ATT+Sign+20230124.pdf | G19: Quote | H19: AT&T | L19: {"mimeType":"application/pdf","reference":{"type":"mediaSetViewItem","mediaSetViewItem":{"mediaSetRid":"ri.mio.main.media-set.7a7aadd5-adcf-42ac-9e71-12078d56f27e","mediaSetViewRid":"ri.mio.main.view.5660cab0-05c2-4700-94bc-c64529e38113","mediaItemRid":"ri.mio.main.media-item.0199713b-dbcf-7ebd-9cc7-6e4ba33fe6f4"}}} | N19: PO3000196864 | P19: Equinix Canada, Ltd. | T19: FALSE | U19: -1 | AK19: ri.mio.main.media-item.0199713b-dbcf-7ebd-9cc7-6e4ba33fe6f4_2_22 | AP19: Patch Panel | AV19: ri.mio.main.media-item.0199713b-dbcf-7ebd-9cc7-6e4ba33fe6f4 | AW19: Quote | BD19: CC00001 | BL19: 0 | BO19: 2 | BP19: ri.mio.main.media-item.0199713b-dbcf-7ebd-9cc7-6e4ba33fe6f4_1 | BT19: 1 | BU19: 22 | BV19: PP-0303:13870771 | BX19: 44896 | CI19: 0 | CM19: FALSE | CN19: 33590
A20: QLI00019 | B20: ri.mio.main.media-item.0199713b-dbcf-7ebd-9cc7-6e4ba33fe6f4 | C20: CAD | D20: Equinix Canada, Ltd. | F20: Quote2-PO3000196864-EQUINIX-ATT+Wipro+Canada_Renewal+Post-Novation+(7+Months)__Quote_Num_1-223208968420+ATT+Sign+20230124.pdf | G20: Quote | H20: AT&T | L20: {"mimeType":"application/pdf","reference":{"type":"mediaSetViewItem","mediaSetViewItem":{"mediaSetRid":"ri.mio.main.media-set.7a7aadd5-adcf-42ac-9e71-12078d56f27e","mediaSetViewRid":"ri.mio.main.view.5660cab0-05c2-4700-94bc-c64529e38113","mediaItemRid":"ri.mio.main.media-item.0199713b-dbcf-7ebd-9cc7-6e4ba33fe6f4"}}} | N20: PO3000196864 | P20: Equinix Canada, Ltd. | T20: FALSE | U20: -1 | AK20: ri.mio.main.media-item.0199713b-dbcf-7ebd-9cc7-6e4ba33fe6f4_2_3 | AP20: AC Circuit - 208v - 20-amp - Three Phase - Redundant | AV20: ri.mio.main.media-item.0199713b-dbcf-7ebd-9cc7-6e4ba33fe6f4 | AW20: Quote | BD20: POW00003 | BJ20: 0 | BO20: 2 | BP20: ri.mio.main.media-item.0199713b-dbcf-7ebd-9cc7-6e4ba33fe6f4_1 | BT20: 1 | BU20: 3 | BV20: 100247283.MT1 | BX20: 44896 | CI20: 0 | CM20: FALSE | CN20: 33590
A21: QLI00020 | B21: ri.mio.main.media-item.0199713b-dbcf-7ebd-9cc7-6e4ba33fe6f4 | C21: CAD | D21: Equinix Canada, Ltd. | F21: Quote2-PO3000196864-EQUINIX-ATT+Wipro+Canada_Renewal+Post-Novation+(7+Months)__Quote_Num_1-223208968420+ATT+Sign+20230124.pdf | G21: Quote | H21: AT&T | L21: {"mimeType":"application/pdf","reference":{"type":"mediaSetViewItem","mediaSetViewItem":{"mediaSetRid":"ri.mio.main.media-set.7a7aadd5-adcf-42ac-9e71-12078d56f27e","mediaSetViewRid":"ri.mio.main.view.5660cab0-05c2-4700-94bc-c64529e38113","mediaItemRid":"ri.mio.main.media-item.0199713b-dbcf-7ebd-9cc7-6e4ba33fe6f4"}}} | N21: PO3000196864 | P21: Equinix Canada, Ltd. | T21: FALSE | U21: -1 | AK21: ri.mio.main.media-item.0199713b-dbcf-7ebd-9cc7-6e4ba33fe6f4_2_4 | AP21: AC Circuit - 208v - 20-amp - Three Phase - Redundant | AV21: ri.mio.main.media-item.0199713b-dbcf-7ebd-9cc7-6e4ba33fe6f4 | AW21: Quote | BD21: POW00003 | BJ21: 0 | BO21: 2 | BP21: ri.mio.main.media-item.0199713b-dbcf-7ebd-9cc7-6e4ba33fe6f4_1 | BT21: 1 | BU21: 4 | BV21: 100245793.MT1 | BX21: 44896 | CI21: 0 | CM21: FALSE | CN21: 33590
A22: QLI00021 | B22: ri.mio.main.media-item.0199713b-dbcf-7ebd-9cc7-6e4ba33fe6f4 | C22: CAD | D22: Equinix Canada, Ltd. | F22: Quote2-PO3000196864-EQUINIX-ATT+Wipro+Canada_Renewal+Post-Novation+(7+Months)__Quote_Num_1-223208968420+ATT+Sign+20230124.pdf | G22: Quote | H22: AT&T | L22: {"mimeType":"application/pdf","reference":{"type":"mediaSetViewItem","mediaSetViewItem":{"mediaSetRid":"ri.mio.main.media-set.7a7aadd5-adcf-42ac-9e71-12078d56f27e","mediaSetViewRid":"ri.mio.main.view.5660cab0-05c2-4700-94bc-c64529e38113","mediaItemRid":"ri.mio.main.media-item.0199713b-dbcf-7ebd-9cc7-6e4ba33fe6f4"}}} | N22: PO3000196864 | P22: Equinix Canada, Ltd. | T22: FALSE | U22: -1 | AK22: ri.mio.main.media-item.0199713b-dbcf-7ebd-9cc7-6e4ba33fe6f4_2_5 | AP22: AC Circuit - 208v - 20-amp - Three Phase - Primary | AV22: ri.mio.main.media-item.0199713b-dbcf-7ebd-9cc7-6e4ba33fe6f4 | AW22: Quote | BD22: POW00003 | BJ22: 0 | BO22: 2 | BP22: ri.mio.main.media-item.0199713b-dbcf-7ebd-9cc7-6e4ba33fe6f4_1 | BT22: 1 | BU22: 5 | BV22: 100245706.MT1 | BX22: 44896 | CI22: 0 | CM22: FALSE | CN22: 33590
A23: QLI00022 | B23: ri.mio.main.media-item.0199713b-dbcf-7ebd-9cc7-6e4ba33fe6f4 | C23: CAD | D23: Equinix Canada, Ltd. | F23: Quote2-PO3000196864-EQUINIX-ATT+Wipro+Canada_Renewal+Post-Novation+(7+Months)__Quote_Num_1-223208968420+ATT+Sign+20230124.pdf | G23: Quote | H23: AT&T | L23: {"mimeType":"application/pdf","reference":{"type":"mediaSetViewItem","mediaSetViewItem":{"mediaSetRid":"ri.mio.main.media-set.7a7aadd5-adcf-42ac-9e71-12078d56f27e","mediaSetViewRid":"ri.mio.main.view.5660cab0-05c2-4700-94bc-c64529e38113","mediaItemRid":"ri.mio.main.media-item.0199713b-dbcf-7ebd-9cc7-6e4ba33fe6f4"}}} | N23: PO3000196864 | P23: Equinix Canada, Ltd. | T23: FALSE | U23: -1 | AK23: ri.mio.main.media-item.0199713b-dbcf-7ebd-9cc7-6e4ba33fe6f4_2_6 | AP23: AC Circuit - 208v - 20-amp - Three Phase - Redundant | AV23: ri.mio.main.media-item.0199713b-dbcf-7ebd-9cc7-6e4ba33fe6f4 | AW23: Quote | BD23: POW00003 | BJ23: 0 | BO23: 2 | BP23: ri.mio.main.media-item.0199713b-dbcf-7ebd-9cc7-6e4ba33fe6f4_1 | BT23: 1 | BU23: 6 | BV23: 100247287.MT1 | BX23: 44896 | CI23: 0 | CM23: FALSE | CN23: 33590
A24: QLI00023 | B24: ri.mio.main.media-item.0199713b-dbcf-7ebd-9cc7-6e4ba33fe6f4 | C24: CAD | D24: Equinix Canada, Ltd. | F24: Quote2-PO3000196864-EQUINIX-ATT+Wipro+Canada_Renewal+Post-Novation+(7+Months)__Quote_Num_1-223208968420+ATT+Sign+20230124.pdf | G24: Quote | H24: AT&T | L24: {"mimeType":"application/pdf","reference":{"type":"mediaSetViewItem","mediaSetViewItem":{"mediaSetRid":"ri.mio.main.media-set.7a7aadd5-adcf-42ac-9e71-12078d56f27e","mediaSetViewRid":"ri.mio.main.view.5660cab0-05c2-4700-94bc-c64529e38113","mediaItemRid":"ri.mio.main.media-item.0199713b-dbcf-7ebd-9cc7-6e4ba33fe6f4"}}} | N24: PO3000196864 | P24: Equinix Canada, Ltd. | T24: FALSE | U24: -1 | AK24: ri.mio.main.media-item.0199713b-dbcf-7ebd-9cc7-6e4ba33fe6f4_2_7 | AP24: AC Circuit - 208v - 20-amp - Three Phase - Primary | AV24: ri.mio.main.media-item.0199713b-dbcf-7ebd-9cc7-6e4ba33fe6f4 | AW24: Quote | BD24: POW00003 | BJ24: 0 | BO24: 2 | BP24: ri.mio.main.media-item.0199713b-dbcf-7ebd-9cc7-6e4ba33fe6f4_1 | BT24: 1 | BU24: 7 | BV24: 100245700.MT1 | BX24: 44896 | CI24: 0 | CM24: FALSE | CN24: 33590
A25: QLI00024 | B25: ri.mio.main.media-item.0199713b-dbcf-7ebd-9cc7-6e4ba33fe6f4 | C25: CAD | D25: Equinix Canada, Ltd. | F25: Quote2-PO3000196864-EQUINIX-ATT+Wipro+Canada_Renewal+Post-Novation+(7+Months)__Quote_Num_1-223208968420+ATT+Sign+20230124.pdf | G25: Quote | H25: AT&T | L25: {"mimeType":"application/pdf","reference":{"type":"mediaSetViewItem","mediaSetViewItem":{"mediaSetRid":"ri.mio.main.media-set.7a7aadd5-adcf-42ac-9e71-12078d56f27e","mediaSetViewRid":"ri.mio.main.view.5660cab0-05c2-4700-94bc-c64529e38113","mediaItemRid":"ri.mio.main.media-item.0199713b-dbcf-7ebd-9cc7-6e4ba33fe6f4"}}} | N25: PO3000196864 | P25: Equinix Canada, Ltd. | T25: FALSE | U25: -1 | AK25: ri.mio.main.media-item.0199713b-dbcf-7ebd-9cc7-6e4ba33fe6f4_2_8 | AP25: AC Circuit - 208v - 20-amp - Three Phase - Redundant | AV25: ri.mio.main.media-item.0199713b-dbcf-7ebd-9cc7-6e4ba33fe6f4 | AW25: Quote | BD25: POW00003 | BJ25: 0 | BO25: 2 | BP25: ri.mio.main.media-item.0199713b-dbcf-7ebd-9cc7-6e4ba33fe6f4_1 | BT25: 1 | BU25: 8 | BV25: 100247281.MT1 | BX25: 44896 | CI25: 0 | CM25: FALSE | CN25: 33590
A26: QLI00025 | B26: ri.mio.main.media-item.0199713b-dbcf-7ebd-9cc7-6e4ba33fe6f4 | C26: CAD | D26: Equinix Canada, Ltd. | F26: Quote2-PO3000196864-EQUINIX-ATT+Wipro+Canada_Renewal+Post-Novation+(7+Months)__Quote_Num_1-223208968420+ATT+Sign+20230124.pdf | G26: Quote | H26: AT&T | L26: {"mimeType":"application/pdf","reference":{"type":"mediaSetViewItem","mediaSetViewItem":{"mediaSetRid":"ri.mio.main.media-set.7a7aadd5-adcf-42ac-9e71-12078d56f27e","mediaSetViewRid":"ri.mio.main.view.5660cab0-05c2-4700-94bc-c64529e38113","mediaItemRid":"ri.mio.main.media-item.0199713b-dbcf-7ebd-9cc7-6e4ba33fe6f4"}}} | N26: PO3000196864 | P26: Equinix Canada, Ltd. | T26: FALSE | U26: -1 | AK26: ri.mio.main.media-item.0199713b-dbcf-7ebd-9cc7-6e4ba33fe6f4_2_9 | AP26: AC Circuit - 208v - 20-amp - Three Phase - Primary | AV26: ri.mio.main.media-item.0199713b-dbcf-7ebd-9cc7-6e4ba33fe6f4 | AW26: Quote | BD26: POW00003 | BJ26: 0 | BO26: 2 | BP26: ri.mio.main.media-item.0199713b-dbcf-7ebd-9cc7-6e4ba33fe6f4_1 | BT26: 1 | BU26: 9 | BV26: 100245795.MT1 | BX26: 44896 | CI26: 0 | CM26: FALSE | CN26: 33590
A27: QLI00026 | B27: ri.mio.main.media-item.0199713b-dbcf-7ebd-9cc7-6e4ba33fe6f4 | C27: CAD | D27: Equinix Canada, Ltd. | F27: Quote2-PO3000196864-EQUINIX-ATT+Wipro+Canada_Renewal+Post-Novation+(7+Months)__Quote_Num_1-223208968420+ATT+Sign+20230124.pdf | G27: Quote | H27: AT&T | L27: {"mimeType":"application/pdf","reference":{"type":"mediaSetViewItem","mediaSetViewItem":{"mediaSetRid":"ri.mio.main.media-set.7a7aadd5-adcf-42ac-9e71-12078d56f27e","mediaSetViewRid":"ri.mio.main.view.5660cab0-05c2-4700-94bc-c64529e38113","mediaItemRid":"ri.mio.main.media-item.0199713b-dbcf-7ebd-9cc7-6e4ba33fe6f4"}}} | N27: PO3000196864 | P27: Equinix Canada, Ltd. | T27: FALSE | U27: -1 | AK27: ri.mio.main.media-item.0199713b-dbcf-7ebd-9cc7-6e4ba33fe6f4_6_1 | AP27: Space & Power | AV27: ri.mio.main.media-item.0199713b-dbcf-7ebd-9cc7-6e4ba33fe6f4 | AW27: Quote | BD27: 20008-LEP-005.1 | BO27: 6 | BU27: 1 | BZ27: MT1 | CA27: MT1 | CM27: FALSE | CN27: 36670
A28: QLI00027 | B28: ri.mio.main.media-item.0199713b-dbcf-7ebd-9cc7-6e4ba33fe6f4 | C28: CAD | D28: Equinix Canada, Ltd. | F28: Quote2-PO3000196864-EQUINIX-ATT+Wipro+Canada_Renewal+Post-Novation+(7+Months)__Quote_Num_1-223208968420+ATT+Sign+20230124.pdf | G28: Quote | H28: AT&T | L28: {"mimeType":"application/pdf","reference":{"type":"mediaSetViewItem","mediaSetViewItem":{"mediaSetRid":"ri.mio.main.media-set.7a7aadd5-adcf-42ac-9e71-12078d56f27e","mediaSetViewRid":"ri.mio.main.view.5660cab0-05c2-4700-94bc-c64529e38113","mediaItemRid":"ri.mio.main.media-item.0199713b-dbcf-7ebd-9cc7-6e4ba33fe6f4"}}} | N28: PO3000196864 | P28: Equinix Canada, Ltd. | T28: FALSE | U28: -1 | AK28: ri.mio.main.media-item.0199713b-dbcf-7ebd-9cc7-6e4ba33fe6f4_6_2 | AP28: Interconnection | AV28: ri.mio.main.media-item.0199713b-dbcf-7ebd-9cc7-6e4ba33fe6f4 | AW28: Quote | BD28: 20008-LEP-005.1 | BO28: 6 | BU28: 2 | BZ28: MT1 | CA28: MT1 | CM28: FALSE | CN28: 36670
A29: QLI00028 | B29: ri.mio.main.media-item.0199713b-dbcf-7ebd-9cc7-6e4ba33fe6f4 | C29: CAD | D29: Equinix Canada, Ltd. | F29: Quote2-PO3000196864-EQUINIX-ATT+Wipro+Canada_Renewal+Post-Novation+(7+Months)__Quote_Num_1-223208968420+ATT+Sign+20230124.pdf | G29: Quote | H29: AT&T | L29: {"mimeType":"application/pdf","reference":{"type":"mediaSetViewItem","mediaSetViewItem":{"mediaSetRid":"ri.mio.main.media-set.7a7aadd5-adcf-42ac-9e71-12078d56f27e","mediaSetViewRid":"ri.mio.main.view.5660cab0-05c2-4700-94bc-c64529e38113","mediaItemRid":"ri.mio.main.media-item.0199713b-dbcf-7ebd-9cc7-6e4ba33fe6f4"}}} | N29: PO3000196864 | P29: Equinix Canada, Ltd. | T29: FALSE | U29: -1 | AK29: ri.mio.main.media-item.0199713b-dbcf-7ebd-9cc7-6e4ba33fe6f4_6_3 | AP29: Services | AV29: ri.mio.main.media-item.0199713b-dbcf-7ebd-9cc7-6e4ba33fe6f4 | AW29: Quote | BO29: 6 | BU29: 3 | BZ29: MT1 | CA29: MT1 | CM29: FALSE | CN29: 36670
A30: QLI00029 | B30: ri.mio.main.media-item.0199713b-e2af-7291-b207-419560cb2e62 | C30: CAD | D30: Equinix Canada, Ltd. | F30: Quote-PO3000196864-EQUINIX-ATT+Wipro+Canada_Renewal+Post-Novation_MT1+OT1_1-222682409611+(37+months)+ATT+Signed+20230119.pdf | G30: Quote | H30: AT&T | L30: {"mimeType":"application/pdf","reference":{"type":"mediaSetViewItem","mediaSetViewItem":{"mediaSetRid":"ri.mio.main.media-set.7a7aadd5-adcf-42ac-9e71-12078d56f27e","mediaSetViewRid":"ri.mio.main.view.5660cab0-05c2-4700-94bc-c64529e38113","mediaItemRid":"ri.mio.main.media-item.0199713b-e2af-7291-b207-419560cb2e62"}}} | N30: PO3000196864 | P30: Equinix Canada, Ltd. | T30: FALSE | U30: -1 | AK30: ri.mio.main.media-item.0199713b-e2af-7291-b207-419560cb2e62_10_1 | AP30: Cabinet - 3.03 kVA - Closed Cabinet | AV30: ri.mio.main.media-item.0199713b-e2af-7291-b207-419560cb2e62 | AW30: Quote | BD30: CAB00001 | BJ30: 0 | BO30: 10 | BP30: ri.mio.main.media-item.0199713b-e2af-7291-b207-419560cb2e62_9 | BT30: 1 | BU30: 1 | BV30: 0216-00087170 | BX30: 44896 | CI30: 0 | CM30: FALSE | CN30: 45445
A31: QLI00030 | B31: ri.mio.main.media-item.0199713b-e2af-7291-b207-419560cb2e62 | C31: CAD | D31: Equinix Canada, Ltd. | F31: Quote-PO3000196864-EQUINIX-ATT+Wipro+Canada_Renewal+Post-Novation_MT1+OT1_1-222682409611+(37+months)+ATT+Signed+20230119.pdf | G31: Quote | H31: AT&T | L31: {"mimeType":"application/pdf","reference":{"type":"mediaSetViewItem","mediaSetViewItem":{"mediaSetRid":"ri.mio.main.media-set.7a7aadd5-adcf-42ac-9e71-12078d56f27e","mediaSetViewRid":"ri.mio.main.view.5660cab0-05c2-4700-94bc-c64529e38113","mediaItemRid":"ri.mio.main.media-item.0199713b-e2af-7291-b207-419560cb2e62"}}} | N31: PO3000196864 | P31: Equinix Canada, Ltd. | T31: FALSE | U31: -1 | AK31: ri.mio.main.media-item.0199713b-e2af-7291-b207-419560cb2e62_10_10 | AP31: Cabinet - 3.03 kVA - Closed Cabinet | AV31: ri.mio.main.media-item.0199713b-e2af-7291-b207-419560cb2e62 | AW31: Quote | BD31: CAB00001 | BJ31: 0 | BO31: 10 | BP31: ri.mio.main.media-item.0199713b-e2af-7291-b207-419560cb2e62_9 | BT31: 1 | BU31: 10 | BV31: 0225-00087179 | BX31: 44896 | CI31: 0 | CM31: FALSE | CN31: 45445
A32: QLI00031 | B32: ri.mio.main.media-item.0199713b-e2af-7291-b207-419560cb2e62 | C32: CAD | D32: Equinix Canada, Ltd. | F32: Quote-PO3000196864-EQUINIX-ATT+Wipro+Canada_Renewal+Post-Novation_MT1+OT1_1-222682409611+(37+months)+ATT+Signed+20230119.pdf | G32: Quote | H32: AT&T | L32: {"mimeType":"application/pdf","reference":{"type":"mediaSetViewItem","mediaSetViewItem":{"mediaSetRid":"ri.mio.main.media-set.7a7aadd5-adcf-42ac-9e71-12078d56f27e","mediaSetViewRid":"ri.mio.main.view.5660cab0-05c2-4700-94bc-c64529e38113","mediaItemRid":"ri.mio.main.media-item.0199713b-e2af-7291-b207-419560cb2e62"}}} | N32: PO3000196864 | P32: Equinix Canada, Ltd. | T32: FALSE | U32: -1 | AK32: ri.mio.main.media-item.0199713b-e2af-7291-b207-419560cb2e62_10_11 | AP32: Cabinet - 3.03 kVA - Closed Cabinet | AV32: ri.mio.main.media-item.0199713b-e2af-7291-b207-419560cb2e62 | AW32: Quote | BD32: CAB00001 | BJ32: 0 | BO32: 10 | BP32: ri.mio.main.media-item.0199713b-e2af-7291-b207-419560cb2e62_9 | BT32: 1 | BU32: 11 | BV32: 0226-00087180 | BX32: 44896 | CI32: 0 | CM32: FALSE | CN32: 45445
A33: QLI00032 | B33: ri.mio.main.media-item.0199713b-e2af-7291-b207-419560cb2e62 | C33: CAD | D33: Equinix Canada, Ltd. | F33: Quote-PO3000196864-EQUINIX-ATT+Wipro+Canada_Renewal+Post-Novation_MT1+OT1_1-222682409611+(37+months)+ATT+Signed+20230119.pdf | G33: Quote | H33: AT&T | L33: {"mimeType":"application/pdf","reference":{"type":"mediaSetViewItem","mediaSetViewItem":{"mediaSetRid":"ri.mio.main.media-set.7a7aadd5-adcf-42ac-9e71-12078d56f27e","mediaSetViewRid":"ri.mio.main.view.5660cab0-05c2-4700-94bc-c64529e38113","mediaItemRid":"ri.mio.main.media-item.0199713b-e2af-7291-b207-419560cb2e62"}}} | N33: PO3000196864 | P33: Equinix Canada, Ltd. | T33: FALSE | U33: -1 | AK33: ri.mio.main.media-item.0199713b-e2af-7291-b207-419560cb2e62_10_12 | AP33: Cage - Customer Provided Cabinet - 48 Cabinets - 182 KVA | AV33: ri.mio.main.media-item.0199713b-e2af-7291-b207-419560cb2e62 | AW33: Quote | BD33: CAG00001 | BJ33: 61425 | BO33: 10 | BP33: ri.mio.main.media-item.0199713b-e2af-7291-b207-419560cb2e62_9 | BT33: 182 | BU33: 12 | BV33: 113995-00078068 | BX33: 44896 | CI33: 61425 | CM33: FALSE | CN33: 45445
A34: QLI00033 | B34: ri.mio.main.media-item.0199713b-e2af-7291-b207-419560cb2e62 | C34: CAD | D34: Equinix Canada, Ltd. | F34: Quote-PO3000196864-EQUINIX-ATT+Wipro+Canada_Renewal+Post-Novation_MT1+OT1_1-222682409611+(37+months)+ATT+Signed+20230119.pdf | G34: Quote | H34: AT&T | L34: {"mimeType":"application/pdf","reference":{"type":"mediaSetViewItem","mediaSetViewItem":{"mediaSetRid":"ri.mio.main.media-set.7a7aadd5-adcf-42ac-9e71-12078d56f27e","mediaSetViewRid":"ri.mio.main.view.5660cab0-05c2-4700-94bc-c64529e38113","mediaItemRid":"ri.mio.main.media-item.0199713b-e2af-7291-b207-419560cb2e62"}}} | N34: PO3000196864 | P34: Equinix Canada, Ltd. | T34: FALSE | U34: -1 | AK34: ri.mio.main.media-item.0199713b-e2af-7291-b207-419560cb2e62_10_13 | AP34: AC Power | AV34: ri.mio.main.media-item.0199713b-e2af-7291-b207-419560cb2e62 | AW34: Quote | BD34: POW00003 | BJ34: 61425 | BO34: 10 | BP34: ri.mio.main.media-item.0199713b-e2af-7291-b207-419560cb2e62_9 | BT34: 182 | BU34: 13 | BV34: 7-10000022957 | BX34: 44896 | CI34: 61425 | CM34: FALSE | CN34: 45445
A35: QLI00034 | B35: ri.mio.main.media-item.0199713b-e2af-7291-b207-419560cb2e62 | C35: CAD | D35: Equinix Canada, Ltd. | F35: Quote-PO3000196864-EQUINIX-ATT+Wipro+Canada_Renewal+Post-Novation_MT1+OT1_1-222682409611+(37+months)+ATT+Signed+20230119.pdf | G35: Quote | H35: AT&T | L35: {"mimeType":"application/pdf","reference":{"type":"mediaSetViewItem","mediaSetViewItem":{"mediaSetRid":"ri.mio.main.media-set.7a7aadd5-adcf-42ac-9e71-12078d56f27e","mediaSetViewRid":"ri.mio.main.view.5660cab0-05c2-4700-94bc-c64529e38113","mediaItemRid":"ri.mio.main.media-item.0199713b-e2af-7291-b207-419560cb2e62"}}} | N35: PO3000196864 | P35: Equinix Canada, Ltd. | T35: FALSE | U35: -1 | AK35: ri.mio.main.media-item.0199713b-e2af-7291-b207-419560cb2e62_10_14 | AP35: AC Circuit - 230v - 30-amp - Single Phase - Primary | AV35: ri.mio.main.media-item.0199713b-e2af-7291-b207-419560cb2e62 | AW35: Quote | BD35: POW00003 | BJ35: 0 | BO35: 10 | BP35: ri.mio.main.media-item.0199713b-e2af-7291-b207-419560cb2e62_9 | BT35: 1 | BU35: 14 | BV35: 100088053.OT1 | BX35: 44896 | CI35: 0 | CM35: FALSE | CN35: 45445
A36: QLI00035 | B36: ri.mio.main.media-item.0199713b-e2af-7291-b207-419560cb2e62 | C36: CAD | D36: Equinix Canada, Ltd. | F36: Quote-PO3000196864-EQUINIX-ATT+Wipro+Canada_Renewal+Post-Novation_MT1+OT1_1-222682409611+(37+months)+ATT+Signed+20230119.pdf | G36: Quote | H36: AT&T | L36: {"mimeType":"application/pdf","reference":{"type":"mediaSetViewItem","mediaSetViewItem":{"mediaSetRid":"ri.mio.main.media-set.7a7aadd5-adcf-42ac-9e71-12078d56f27e","mediaSetViewRid":"ri.mio.main.view.5660cab0-05c2-4700-94bc-c64529e38113","mediaItemRid":"ri.mio.main.media-item.0199713b-e2af-7291-b207-419560cb2e62"}}} | N36: PO3000196864 | P36: Equinix Canada, Ltd. | T36: FALSE | U36: -1 | AK36: ri.mio.main.media-item.0199713b-e2af-7291-b207-419560cb2e62_10_15 | AP36: AC Circuit - 230v - 30-amp - Single Phase - Redundant | AV36: ri.mio.main.media-item.0199713b-e2af-7291-b207-419560cb2e62 | AW36: Quote | BD36: POW00003 | BJ36: 0 | BO36: 10 | BP36: ri.mio.main.media-item.0199713b-e2af-7291-b207-419560cb2e62_9 | BT36: 1 | BU36: 15 | BV36: 100088054.OT1 | BX36: 44896 | CI36: 0 | CM36: FALSE | CN36: 45445
A37: QLI00036 | B37: ri.mio.main.media-item.0199713b-e2af-7291-b207-419560cb2e62 | C37: CAD | D37: Equinix Canada, Ltd. | F37: Quote-PO3000196864-EQUINIX-ATT+Wipro+Canada_Renewal+Post-Novation_MT1+OT1_1-222682409611+(37+months)+ATT+Signed+20230119.pdf | G37: Quote | H37: AT&T | L37: {"mimeType":"application/pdf","reference":{"type":"mediaSetViewItem","mediaSetViewItem":{"mediaSetRid":"ri.mio.main.media-set.7a7aadd5-adcf-42ac-9e71-12078d56f27e","mediaSetViewRid":"ri.mio.main.view.5660cab0-05c2-4700-94bc-c64529e38113","mediaItemRid":"ri.mio.main.media-item.0199713b-e2af-7291-b207-419560cb2e62"}}} | N37: PO3000196864 | P37: Equinix Canada, Ltd. | T37: FALSE | U37: -1 | AK37: ri.mio.main.media-item.0199713b-e2af-7291-b207-419560cb2e62_10_16 | AP37: AC Circuit - 230v - 30-amp - Single Phase - Primary | AV37: ri.mio.main.media-item.0199713b-e2af-7291-b207-419560cb2e62 | AW37: Quote | BD37: POW00003 | BJ37: 0 | BO37: 10 | BP37: ri.mio.main.media-item.0199713b-e2af-7291-b207-419560cb2e62_9 | BT37: 1 | BU37: 16 | BV37: 100088057.OT1 | BX37: 44896 | CI37: 0 | CM37: FALSE | CN37: 45445
A38: QLI00037 | B38: ri.mio.main.media-item.0199713b-e2af-7291-b207-419560cb2e62 | C38: CAD | D38: Equinix Canada, Ltd. | F38: Quote-PO3000196864-EQUINIX-ATT+Wipro+Canada_Renewal+Post-Novation_MT1+OT1_1-222682409611+(37+months)+ATT+Signed+20230119.pdf | G38: Quote | H38: AT&T | L38: {"mimeType":"application/pdf","reference":{"type":"mediaSetViewItem","mediaSetViewItem":{"mediaSetRid":"ri.mio.main.media-set.7a7aadd5-adcf-42ac-9e71-12078d56f27e","mediaSetViewRid":"ri.mio.main.view.5660cab0-05c2-4700-94bc-c64529e38113","mediaItemRid":"ri.mio.main.media-item.0199713b-e2af-7291-b207-419560cb2e62"}}} | N38: PO3000196864 | P38: Equinix Canada, Ltd. | T38: FALSE | U38: -1 | AK38: ri.mio.main.media-item.0199713b-e2af-7291-b207-419560cb2e62_10_17 | AP38: AC Circuit - 230v - 30-amp - Single Phase - Redundant | AV38: ri.mio.main.media-item.0199713b-e2af-7291-b207-419560cb2e62 | AW38: Quote | BD38: POW00003 | BJ38: 0 | BO38: 10 | BP38: ri.mio.main.media-item.0199713b-e2af-7291-b207-419560cb2e62_9 | BT38: 1 | BU38: 17 | BV38: 100088058.OT1 | BX38: 44896 | CI38: 0 | CM38: FALSE | CN38: 45445
A39: QLI00038 | B39: ri.mio.main.media-item.0199713b-e2af-7291-b207-419560cb2e62 | C39: CAD | D39: Equinix Canada, Ltd. | F39: Quote-PO3000196864-EQUINIX-ATT+Wipro+Canada_Renewal+Post-Novation_MT1+OT1_1-222682409611+(37+months)+ATT+Signed+20230119.pdf | G39: Quote | H39: AT&T | L39: {"mimeType":"application/pdf","reference":{"type":"mediaSetViewItem","mediaSetViewItem":{"mediaSetRid":"ri.mio.main.media-set.7a7aadd5-adcf-42ac-9e71-12078d56f27e","mediaSetViewRid":"ri.mio.main.view.5660cab0-05c2-4700-94bc-c64529e38113","mediaItemRid":"ri.mio.main.media-item.0199713b-e2af-7291-b207-419560cb2e62"}}} | N39: PO3000196864 | P39: Equinix Canada, Ltd. | T39: FALSE | U39: -1 | AK39: ri.mio.main.media-item.0199713b-e2af-7291-b207-419560cb2e62_10_18 | AP39: AC Circuit - 230v - 30-amp - Single Phase - Primary | AV39: ri.mio.main.media-item.0199713b-e2af-7291-b207-419560cb2e62 | AW39: Quote | BD39: POW00003 | BJ39: 0 | BO39: 10 | BP39: ri.mio.main.media-item.0199713b-e2af-7291-b207-419560cb2e62_9 | BT39: 1 | BU39: 18 | BV39: 100088059.OT1 | BX39: 44896 | CI39: 0 | CM39: FALSE | CN39: 45445
A40: QLI00039 | B40: ri.mio.main.media-item.0199713b-e2af-7291-b207-419560cb2e62 | C40: CAD | D40: Equinix Canada, Ltd. | F40: Quote-PO3000196864-EQUINIX-ATT+Wipro+Canada_Renewal+Post-Novation_MT1+OT1_1-222682409611+(37+months)+ATT+Signed+20230119.pdf | G40: Quote | H40: AT&T | L40: {"mimeType":"application/pdf","reference":{"type":"mediaSetViewItem","mediaSetViewItem":{"mediaSetRid":"ri.mio.main.media-set.7a7aadd5-adcf-42ac-9e71-12078d56f27e","mediaSetViewRid":"ri.mio.main.view.5660cab0-05c2-4700-94bc-c64529e38113","mediaItemRid":"ri.mio.main.media-item.0199713b-e2af-7291-b207-419560cb2e62"}}} | N40: PO3000196864 | P40: Equinix Canada, Ltd. | T40: FALSE | U40: -1 | AK40: ri.mio.main.media-item.0199713b-e2af-7291-b207-419560cb2e62_10_19 | AP40: AC Circuit - 230v - 30-amp - Single Phase - Redundant | AV40: ri.mio.main.media-item.0199713b-e2af-7291-b207-419560cb2e62 | AW40: Quote | BD40: POW00003 | BJ40: 0 | BO40: 10 | BP40: ri.mio.main.media-item.0199713b-e2af-7291-b207-419560cb2e62_9 | BT40: 1 | BU40: 19 | BV40: 100088060.OT1 | BX40: 44896 | CI40: 0 | CM40: FALSE | CN40: 45445
...

Sheet Sheet1
A1: Item Code | B1: Unique Ones | E1: Serial Number
A2: SPC00002 | B2: ACC000001 | E2: 7-100000400339 | G2: =COUNTIFS(Sheet2!B3:B15782,E2) -> 0
A3: CAG00001 | B3: ACC00001 | E3: 0811814 | G3: =COUNTIFS(Sheet2!B4:B15783,E3) -> 0
A4: POW00001 | B4: ACC000010 | E4: 7-100000401078 | G4: =COUNTIFS(Sheet2!B5:B15784,E4) -> 0
A5: POW00003 | B5: ACC000011 | E5: 100247282.MT1 | G5: =COUNTIFS(Sheet2!B6:B15785,E5) -> 0
A6: CAB00001 | B6: ACC00008 | E6: 0204-00121279 | G6: =COUNTIFS(Sheet2!B7:B15786,E6) -> 0
A7: CAB00001 | B7: ACC00009 | E7: 0201-00121276 | G7: =COUNTIFS(Sheet2!B8:B15787,E7) -> 0
A8: CAB00001 | B8: ACC00010 | E8: 0126-00121273 | G8: =COUNTIFS(Sheet2!B9:B15788,E8) -> 0
A9: CAB00001 | B9: ACC00110 | E9: 0209-00121278 | G9: =COUNTIFS(Sheet2!B10:B15789,E9) -> 0
A10: CC00004 | B10: BA00001 | E10: 0000-00726560 | G10: =COUNTIFS(Sheet2!B11:B15790,E10) -> 0
A11: CAB00001 | B11: BUNDLE00001 | E11: 0301-00121280 | G11: =COUNTIFS(Sheet2!B12:B15791,E11) -> 0
A12: CC00001 | B12: BUNDLE00002 | E12: 7-10000394303 | G12: =COUNTIFS(Sheet2!B13:B15792,E12) -> 0
A13: CC00001 | B13: BUNDLEC0002 | E13: 100168372 | G13: =COUNTIFS(Sheet2!B14:B15793,E13) -> 1
A14: PS00004 | B14: BUNDLEE00002 | E14: 7-10000800310 | G14: =COUNTIFS(Sheet2!B15:B15794,E14) -> 0
A15: CC00001 | B15: C000001 | E15: PWP-000-1000529 | G15: =COUNTIFS(Sheet2!B16:B15795,E15) -> 0
A16: POW00003 | B16: C000004 | E16: 100247288.MT1 | G16: =COUNTIFS(Sheet2!B17:B15796,E16) -> 0
A17: PS00004 | B17: C000016 | E17: 7-10000837239 | G17: =COUNTIFS(Sheet2!B18:B15797,E17) -> 0
A18: CC00001 | B18: CA000001 | E18: PP-0303:13870772 | G18: =COUNTIFS(Sheet2!B19:B15798,E18) -> 0
A19: CC00001 | B19: CA000011 | E19: PP-0303:13870771 | G19: =COUNTIFS(Sheet2!B20:B15799,E19) -> 0
A20: POW00003 | B20: CA60001 | E20: 100247283.MT1 | G20: =COUNTIFS(Sheet2!B21:B15800,E20) -> 0
A21: POW00003 | B21: CA900001 | E21: 100245793.MT1 | G21: =COUNTIFS(Sheet2!B22:B15801,E21) -> 0
A22: POW00003 | B22: CAB000001 | E22: 100245706.MT1 | G22: =COUNTIFS(Sheet2!B23:B15802,E22) -> 0
A23: POW00003 | B23: CAB000002 | E23: 100247287.MT1 | G23: =COUNTIFS(Sheet2!B24:B15803,E23) -> 0
A24: POW00003 | B24: CAB00001 | E24: 100245700.MT1 | G24: =COUNTIFS(Sheet2!B25:B15804,E24) -> 0
A25: POW00003 | B25: CAB00002 | E25: 100247281.MT1 | G25: =COUNTIFS(Sheet2!B26:B15805,E25) -> 0
A26: POW00003 | B26: CAB0001 | E26: 100245795.MT1 | G26: =COUNTIFS(Sheet2!B27:B15806,E26) -> 0
A27: 20008-LEP-005.1 | B27: CAG000001 | G27: =COUNTIFS(Sheet2!B28:B15807,E27) -> 0
A28: 20008-LEP-005.1 | B28: CAG00001 | E28: 0216-00087170 | G28: =COUNTIFS(Sheet2!B29:B15808,E28) -> 1
B29: CAG00002 | E29: 0225-00087179 | G29: =COUNTIFS(Sheet2!B30:B15809,E29) -> 1
A30: CAB00001 | B30: CAG000042 | E30: 0226-00087180 | G30: =COUNTIFS(Sheet2!B31:B15810,E30) -> 1
A31: CAB00001 | B31: CAG00005 | E31: 113995-00078068 | G31: =COUNTIFS(Sheet2!B32:B15811,E31) -> 0
A32: CAB00001 | B32: CAG00006 | E32: 7-10000022957 | G32: =COUNTIFS(Sheet2!B33:B15812,E32) -> 0
A33: CAG00001 | B33: CAG00007 | E33: 100088053.OT1 | G33: =COUNTIFS(Sheet2!B34:B15813,E33) -> 0
A34: POW00003 | B34: CAG00008 | E34: 100088054.OT1 | G34: =COUNTIFS(Sheet2!B35:B15814,E34) -> 0
A35: POW00003 | B35: CAG0001 | E35: 100088057.OT1 | G35: =COUNTIFS(Sheet2!B36:B15815,E35) -> 0
A36: POW00003 | B36: CAQ00001 | E36: 100088058.OT1 | G36: =COUNTIFS(Sheet2!B37:B15816,E36) -> 0
A37: POW00003 | B37: CAQ0001 | E37: 100088059.OT1 | G37: =COUNTIFS(Sheet2!B38:B15817,E37) -> 0
A38: POW00003 | B38: CC000001 | E38: 100088060.OT1 | G38: =COUNTIFS(Sheet2!B39:B15818,E38) -> 0
A39: POW00003 | B39: CC00001 | E39: 0217-00087171 | G39: =COUNTIFS(Sheet2!B40:B15819,E39) -> 1
A40: POW00003 | B40: CC000011 | E40: 100088061.OT1 | G40: =COUNTIFS(Sheet2!B41:B15820,E40) -> 0
...

Sheet Sheet2
B3: 23255328
B4: 23254510
B5: 23254558
B6: 23255333
B7: ANT:0205:1299536
B8: ANT:0204:1299537
B9: ANT:0708:1128198
B10: ANT:0102:1171730
B11: ANT:2303:1171705
B12: 23247655
B13: ANT:2308:1100576
B14: 23247662
B15: 23254720
B16: 23254717
B17: ANT:0103:1299605
B18: ANT:0102:1299643
B19: 23255313
B20: ANT:0101:1302165
B21: 23255440
B22: 0220-22730038
B23: 0320-22742153
B24: 0319-22742150
B25: 0219-22730035
B26: 0106-21178082
B27: 0103-21178083
B28: 0202-20449865
B29: 0201-21267825
B30: 0112-22177009
B31: 0102-21178070
B32: 0104-21178081
B33: 0105-21178085
... B342: 0207-20938274
B343: 100144616
B344: 0000-21891100
B345: 0104-21920581
B346: 0204-21920602
B347: 0311-21920579
B348: 0209-21920607
B349: 0202-21920600
B350: 0309-21920590
...
